<mujoco model="cloth">
  <worldbody>
    <body>
        <body name="object">
        	<inertial pos="0.0 0 0" mass="1.0" diaginertia="1 1 1" />	
        	<joint armature="0" damping="0" limited="false" name="root" pos="0 0 0" stiffness="0" type="free"/>
        	<body name="object2">
				<geom size="0.01 0.3" pos="0 0 0" friction="100" type="cylinder" rgba="1 1 1 1" group="0"/>
				<joint type="hinge" pos="0 0.04 0" damping="0.1" range="-45 45" axis="0 0 1"/>
		    		<body name="object3">
					<geom size="0.01 0.3" pos="0 0.04 0" type="cylinder" rgba="1 1 1 1" group="0"/>
					<joint type="hinge" pos="0 0.08 0" damping="0.1" range="-45 45" axis="0 0 1"/>
					<body name="object4">
						<geom size="0.01 0.3" pos="0 0.08 0" type="cylinder" rgba="1 1 1 1" group="0"/>
						<joint type="hinge" pos="0 0.12 0" damping="0.1" range="-45 45" axis="0 0 1"/>
						<body name="object5">
							<geom size="0.01 0.3" pos="0 0.12 0" type="cylinder" rgba="1 1 1 1" group="0"/>
							<joint type="hinge" pos="0 0.16 0" damping="0.1" range="-45 45" axis="0 0 1"/>
							<body name="object6">
								<geom size="0.01 0.3" pos="0 0.16 0" type="cylinder" rgba="1 1 1 1" group="0"/>
								<joint type="hinge" pos="0 0.20 0" damping="0.1" range="-45 45" axis="0 0 1"/>
								<body name="object7">
									<geom size="0.01 0.3" pos="0 0.20 0" type="cylinder" rgba="1 1 1 1" group="0"/>
									<joint type="hinge" pos="0 0.24 0" damping="0.1" range="-45 45" axis="0 0 1"/>
									<body name="object8">
										<geom size="0.01 0.3" pos="0 0.24 0" type="cylinder" rgba="1 1 1 1" group="0"/>
										<joint type="hinge" pos="0 0.28 0" damping="0.1" range="-45 45" axis="0 0 1"/>
										<body name="object9">
											<geom size="0.01 0.3" pos="0 0.28 0" type="cylinder" rgba="1 1 1 1" group="0"/>
											<joint type="hinge" pos="0 0.32 0" damping="0.1" range="-45 45" axis="0 0 1"/>
											<body name="object10">
												<geom size="0.01 0.3" pos="0 0.32 0" type="cylinder" rgba="1 1 1 1" group="0"/>
												<joint type="hinge" pos="0 0.36 0" damping="0.1" range="-45 45" axis="0 0 1"/>
												<body name="object11">
													<geom size="0.01 0.3" pos="0 0.36 0" type="cylinder" rgba="1 1 1 1" group="0"/>
													<joint type="hinge" pos="0 0.40 0" damping="0.1" range="-45 45" axis="0 0 1"/>
													<body name="object12">
														<geom size="0.01 0.3" pos="0 0.40 0" type="cylinder" rgba="1 1 1 1" group="0"/>
														<joint type="hinge" pos="0 0.44 0" damping="0.1" range="-45 45" axis="0 0 1"/>
														<geom size="0.01 0.3" pos="0 0.44 0" type="cylinder" rgba="1 1 1 1" group="0"/>
													</body>
												</body>
											</body>
										</body>
									</body>
								</body>
							</body>
						</body>
					</body>
				</body>
			</body>
        </body>
        <site name="bottom_site" rgba="0 0 0 0" size="0.005"/>
        <site name="top_site" rgba="0 0 0 0" size="0.005"/>
        <site name="horizontal_radius_site" rgba="0 0 0 0" size="0.1"/>
    </body>
  </worldbody>
</mujoco>
