<mujoco model="cloth_hand">
    <worldbody>
        <body name="cloth_base" pos="0 0 0">
            <site name="ft_frame" pos="0 0 0" size="0.01 0.01 0.01" rgba="1 0 0 1" type="sphere" group="1"/>
            <inertial pos="0 0 0" mass="3e-1" diaginertia="1e-2 1e-2 1e-2" />
            <body name="eef" pos="0 0 0" quat="0.707105 0 0 -0.707105">
                <site name="grip_site" pos="0 0 0" size="0.01 0.01 0.01" rgba="1 0 0 0.5" type="sphere" group="1"/>
                <site name="ee_x" pos="0.1 0 0" size="0.005 .1"  quat="0.707105  0 0.707108 0 " rgba="1 0 0 0" type="cylinder" group="1"/>
                <site name="ee_y" pos="0 0.1 0" size="0.005 .1" quat="0.707105 0.707108 0 0" rgba="0 1 0 0" type="cylinder" group="1"/>
                <site name="ee_z" pos="0 0 0.1" size="0.005 .1" quat="1 0 0 0" rgba="0 0 1 0" type="cylinder" group="1"/>
                <site name="grip_site_cylinder" pos="0 0 0" size="0.005 10" rgba="0 1 0 0.3" type="cylinder" group="1"/>
            </body>
        	
        	<body name="object" quat="0.707 0.707 0 0">
        		<inertial pos="0.022 0 0" mass="0.01" diaginertia="7.89997e-07 7.89997e-07 8e-08" />
        		<geom size="0.01 0.3" pos="0 0 0" type="cylinder" rgba="1 1 1 1" group="0"/>
        		<joint name="joint0" type="hinge" pos="0 0.04 0" damping="13" range="-45 45" axis="0 0 1"/>
		    	<body name="object3">
					<geom size="0.01 0.3" pos="0 0.04 0" type="cylinder" rgba="1 1 1 1" group="0"/>
					<joint name="joint1" type="hinge" pos="0 0.08 0" damping="13" range="-45 45" axis="0 0 1"/>
					<body name="object4">
						<geom size="0.01 0.3" pos="0 0.08 0" type="cylinder" rgba="1 1 1 1" group="0"/>
						<joint name="joint2" type="hinge" pos="0 0.12 0" damping="13" range="-45 45" axis="0 0 1"/>
						<body name="object5">
							<geom size="0.01 0.3" pos="0 0.12 0" type="cylinder" rgba="1 1 1 1" group="0"/>
							<joint name="joint3" type="hinge" pos="0 0.16 0" damping="13" range="-45 45" axis="0 0 1"/>
							<body name="object6">
								<geom size="0.01 0.3" pos="0 0.16 0" type="cylinder" rgba="1 1 1 1" group="0"/>
								<joint name="joint4" type="hinge" pos="0 0.20 0" damping="13" range="-45 45" axis="0 0 1"/>
								<body name="object7">
									<geom size="0.01 0.3" pos="0 0.20 0" type="cylinder" rgba="1 1 1 1" group="0"/>
									<joint name="joint5" type="hinge" pos="0 0.24 0" damping="13" range="-45 45" axis="0 0 1"/>
									<body name="object8">
										<geom size="0.01 0.3" pos="0 0.24 0" type="cylinder" rgba="1 1 1 1" group="0"/>
										<joint name="joint6" type="hinge" pos="0 0.28 0" damping="13" range="-45 45" axis="0 0 1"/>
										<body name="object9">
											<geom size="0.01 0.3" pos="0 0.28 0" type="cylinder" rgba="1 1 1 1" group="0"/>
											<joint name="joint7" type="hinge" pos="0 0.32 0" damping="13" range="-45 45" axis="0 0 1"/>
											<body name="object10">
												<geom size="0.01 0.3" pos="0 0.32 0" type="cylinder" rgba="1 1 1 1" group="0"/>
												<joint name="joint8" type="hinge" pos="0 0.36 0" damping="13" range="-45 45" axis="0 0 1"/>
												<body name="object11">
													<geom size="0.01 0.3" pos="0 0.36 0" type="cylinder" rgba="1 1 1 1" group="0"/>
													<joint name="joint9" type="hinge" pos="0 0.40 0" damping="13" range="-45 45" axis="0 0 1"/>
													<body name="object12">
														<geom size="0.01 0.3" pos="0 0.40 0" type="cylinder" rgba="1 1 1 1" group="0"/>
														<joint name="joint10" type="hinge" pos="0 0.44 0" damping="13" range="-45 45" axis="0 0 1"/>
														<geom size="0.01 0.3" pos="0 0.44 0" type="cylinder" rgba="1 1 1 1" group="0"/>
													</body>
												</body>
											</body>
										</body>
									</body>
								</body>
							</body>
						</body>
					</body>
				</body>
        	</body>
        </body>
    </worldbody>
    <sensor>
        <force name="force_ee" site="ft_frame"/>
        <torque name="torque_ee" site="ft_frame"/>
    </sensor>
</mujoco>
