<mujoco model="cloth_hand">
	
	<default>
		<default class="cloth_joint">
			<joint axis="0 0 1" frictionloss="3" range="-55 55" springdamper="0.002 2" type="hinge" />
		</default>
	</default>
    <worldbody>
        <body name="cloth_base" pos="0 0 0">
            <site group="1" name="ft_frame" pos="0 0 0" rgba="1 0 0 1" size="0.01 0.01 0.01" type="sphere" />
            <body name="eef" pos="0 0 0" quat="0.707105 0 0 -0.707105">
                <site group="1" name="grip_site" pos="0 0 0" rgba="1 0 0 0.5" size="0.01 0.01 0.01" type="sphere" />
                <site group="1" name="ee_x" pos="0.1 0 0" quat="0.707105  0 0.707108 0 " rgba="1 0 0 0" size="0.005 .1" type="cylinder" />
                <site group="1" name="ee_y" pos="0 0.1 0" quat="0.707105 0.707108 0 0" rgba="0 1 0 0" size="0.005 .1" type="cylinder" />
                <site group="1" name="ee_z" pos="0 0 0.1" quat="1 0 0 0" rgba="0 0 1 0" size="0.005 .1" type="cylinder" />
                <site group="1" name="grip_site_cylinder" pos="0 0 0" rgba="0 1 0 0.3" size="0.005 10" type="cylinder" />
            </body>
        	
        	<body name="object_anchor" quat="0.707 0.707 0 0">
        		<inertial diaginertia="1e-09 1e-09 1e-9" mass="6e-4" pos="0 0 0" />
        		<geom group="0" name="anchor" pos="0 0.229 0" rgba="1 1 1 1" size="0.01 0.3" type="cylinder" />
        		<site name="anchor_left" pos="0.017 0.229 0.0" />
        		<site name="anchor_right" pos="-0.017 0.229 0.0" />
        		
				
						<body name="object1">
							<geom group="0" name="geom1" pos="0 0.2495 0" rgba="1 1 1 1" size="0.01 0.2115" type="cylinder" />
							<joint class="cloth_joint" name="joint0" pos="0 0.229 0" />
							<site name="site1_left" pos="0.017 0.2495 0.0" />
							<site name="site1_right" pos="-0.017 0.2495 0.0" />
							<body name="object2">
								<geom group="0" name="geom2" pos="0 0.27 0" rgba="1 1 1 1" size="0.01 0.2115" type="cylinder" />
								<joint class="cloth_joint" name="joint1" pos="0 0.2495 0" />
								<site name="site2_left" pos="0.017 0.27 0.0" />
								<site name="site2_right" pos="-0.017 0.27 0.0" />
								<body name="object3">
									<geom group="0" name="geom3" pos="0 0.2905 0" rgba="1 1 1 1" size="0.01 0.2115" type="cylinder" />
									<joint class="cloth_joint" name="joint2" pos="0 0.27 0" />
									<site name="site3_left" pos="0.017 0.2905 0.0" />
									<site name="site3_right" pos="-0.017 0.2905 0.0" />
									<body name="object4">
										<geom group="0" name="geom4" pos="0 0.311 0" rgba="1 1 1 1" size="0.01 0.2115" type="cylinder" />
										<joint class="cloth_joint" name="joint3" pos="0 0.2905 0" />
										<site name="site4_left" pos="0.017 0.311 0.0" />
										<site name="site4_right" pos="-0.017 0.311 0.0" />
										<body name="object5">
											<geom group="0" name="geom5" pos="0 0.3315 0" rgba="1 1 1 1" size="0.01 0.2115" type="cylinder" />
											<joint class="cloth_joint" name="joint4" pos="0 0.311 0" />
											<site name="site5_left" pos="0.017 0.3315 0.0" />
											<site name="site5_right" pos="-0.017 0.3315 0.0" />
											<body name="object6">
												<geom group="0" name="geom6" pos="0 0.352 0" rgba="1 1 1 1" size="0.01 0.2115" type="cylinder" />
												<joint class="cloth_joint" name="joint5" pos="0 0.3315 0" />
												<site name="site6_left" pos="0.017 0.352 0.0" />
												<site name="site6_right" pos="-0.017 0.352 0.0" />
												<body name="object7">
													<geom group="0" name="geom7" pos="0 0.3725 0" rgba="1 1 1 1" size="0.01 0.2115" type="cylinder" />
													<joint class="cloth_joint" name="joint6" pos="0 0.352 0" />
													<site name="site7_left" pos="0.017 0.3725 0.0" />
													<site name="site7_right" pos="-0.017 0.3725 0.0" />
													<body name="object8">
														<geom group="0" name="geom8" pos="0 0.393 0" rgba="1 1 1 1" size="0.01 0.2115" type="cylinder" />
														<joint class="cloth_joint" name="joint7" pos="0 0.3725 0" />
														<site name="site8_left" pos="0.017 0.393 0.0" />
														<site name="site8_right" pos="-0.017 0.393 0.0" />
														<body name="object9">
															<geom group="0" name="geom9" pos="0 0.4135 0" rgba="1 1 1 1" size="0.01 0.2115" type="cylinder" />
															<joint class="cloth_joint" name="joint8" pos="0 0.393 0" />
															<site name="site9_left" pos="0.017 0.4135 0.0" />
															<site name="site9_right" pos="-0.017 0.4135 0.0" />
														</body>
													</body>
												</body>
											</body>
										</body>
									</body>
								</body>
							</body>
						</body>
        	</body>
      </body>
    </worldbody>
    <sensor>
        <force name="force_ee" site="ft_frame" />
        <torque name="torque_ee" site="ft_frame" />
    </sensor>
	<tendon>
    	<spatial damping="1" frictionloss="3" name="tendon1" stiffness="1">
			<site site="anchor_left" /> 
			<geom geom="geom1" sidesite="gripper0_site1_left" />
			<site site="site2_left" />
			<geom geom="geom3" sidesite="gripper0_site3_left" />
			<site site="site4_left" />
			<geom geom="geom5" sidesite="gripper0_site5_left" />
			<site site="site6_left" />
			<geom geom="geom7" sidesite="gripper0_site7_left" />
			<site site="site8_left" />
		</spatial>
		<spatial damping="1" frictionloss="3" name="tendon2" stiffness="1">
			<site site="anchor_left" />
			<geom geom="geom2" sidesite="gripper0_site2_left" />
			<site site="site3_left" />
			<geom geom="geom4" sidesite="gripper0_site4_left" />
			<site site="site5_left" />
			<geom geom="geom6" sidesite="gripper0_site6_left" />
			<site site="site7_left" />
			<geom geom="geom8" sidesite="gripper0_site8_left" />
			<site site="site9_left" />
		</spatial>
		<spatial damping="1" frictionloss="3" name="tendon3" stiffness="1">
			<site site="anchor_right" /> 
			<geom geom="geom1" sidesite="gripper0_site1_right" />
			<site site="site2_right" />
			<geom geom="geom3" sidesite="gripper0_site3_right" />
			<site site="site4_right" />
			<geom geom="geom5" sidesite="gripper0_site5_right" />
			<site site="site6_right" />
			<geom geom="geom7" sidesite="gripper0_site7_right" />
			<site site="site8_right" />
		</spatial>
		<spatial damping="1" frictionloss="3" name="tendon4" stiffness="1">
			<site site="anchor_right" />
			<geom geom="geom2" sidesite="gripper0_site2_right" />
			<site site="site3_right" />
			<geom geom="geom4" sidesite="gripper0_site4_right" />
			<site site="site5_right" />
			<geom geom="geom6" sidesite="gripper0_site6_right" />
			<site site="site7_right" />
			<geom geom="geom8" sidesite="gripper0_site8_right" />
			<site site="site9_right" />
		</spatial>
	</tendon>
    
</mujoco>